<?xml version="1.0" ?>
<!-- =================================================================================== -->
<!-- |    This document was autogenerated by xacro from walking_robot.xacro            | -->
<!-- |    EDITING THIS FILE BY HAND IS NOT RECOMMENDED                                 | -->
<!-- =================================================================================== -->
<!--Namespace specification, mandatory for the file to parse properly.-->
<robot name="walking_robot" xmlns:xacro="http://www.ros.org/wiki/xacro">
  <!-- TODO:
		- Add inertia
		- Add mass
-->
  <!--/////////////////////////////////////////////////////////MACROS DEFINITION\\\\\\\\\\\\\\\\\\\\\\\\\\\\\\\\\\\\\\\\\\\\\\\\\\\\\\

	
	Using xacro we can define macros to reduce repetition in the code and simplify the modification of URDF file.
    To generate the actual URDF file, run in a shell (roscore needed):
    	rosrun xacro xacro model.xacro > model.urdf
-->
  <!--///////////////////////////////////////////////////////////Constants\\\\\\\\\\\\\\\\\\\\\\\\\\\\\\\\\\\\\\\\\\\\\\\\\\\\\\\\\-->
  <!--Leg Macro-->
  <!--////////////////////////////////////////////////////////ROBOT DEFINITION\\\\\\\\\\\\\\\\\\\\\\\\\\\\\\\\\\\\\\\\\\\\\\\\\\\\\-->
  <!--World-->
  <!--	<link name="world" />-->
  <!--Robot base-->
  <link name="walker_base">
    <visual>
      <geometry>
        <box size="0.15 0.3 0.02"/>
      </geometry>
      <material name="mat">
        <color rgba="0 0 0 1"/>
      </material>
    </visual>
  </link>
  <link name="link_1_FL">
    <visual>
      <geometry>
        <cylinder length="0.1" radius="0.02"/>
      </geometry>
      <origin rpy="1.57079632679 0 0" xyz="0 0.05 0"/>
      <material name="mat_FL">
        <color rgba="1.0 0.5 0.5 1.0"/>
      </material>
    </visual>
    <collision>
      <geometry>
        <cylinder length="0.1" radius="0.02"/>
      </geometry>
      <origin rpy="1.57079632679 0 0" xyz="0 0.05 0"/>
    </collision>
  </link>
  <link name="link_2_FL">
    <visual>
      <geometry>
        <cylinder length="0.15" radius="0.02"/>
      </geometry>
      <origin rpy="1.57079632679 0 0" xyz="0 0.075 0"/>
      <material name="mat_FL">
        <color rgba="1.0 0.5 0.5 1.0"/>
      </material>
    </visual>
    <collision>
      <geometry>
        <cylinder length="0.15" radius="0.02"/>
      </geometry>
      <origin rpy="1.57079632679 0 0" xyz="0 0.075 0"/>
    </collision>
  </link>
  <link name="link_3_FL">
    <visual>
      <geometry>
        <cylinder length="0.3" radius="0.02"/>
      </geometry>
      <origin rpy="1.57079632679 0 0" xyz="0 0.15 0"/>
      <material name="mat_FL">
        <color rgba="1.0 0.5 0.5 1.0"/>
      </material>
    </visual>
    <collision>
      <geometry>
        <cylinder length="0.3" radius="0.02"/>
      </geometry>
      <origin rpy="1.57079632679 0 0" xyz="0 0.15 0"/>
    </collision>
  </link>
  <link name="link_1_FR">
    <visual>
      <geometry>
        <cylinder length="0.1" radius="0.02"/>
      </geometry>
      <origin rpy="1.57079632679 0 0" xyz="0 0.05 0"/>
      <material name="mat_FR">
        <color rgba="1.0 0.5 0.5 1.0"/>
      </material>
    </visual>
    <collision>
      <geometry>
        <cylinder length="0.1" radius="0.02"/>
      </geometry>
      <origin rpy="1.57079632679 0 0" xyz="0 0.05 0"/>
    </collision>
  </link>
  <link name="link_2_FR">
    <visual>
      <geometry>
        <cylinder length="0.15" radius="0.02"/>
      </geometry>
      <origin rpy="1.57079632679 0 0" xyz="0 0.075 0"/>
      <material name="mat_FR">
        <color rgba="1.0 0.5 0.5 1.0"/>
      </material>
    </visual>
    <collision>
      <geometry>
        <cylinder length="0.15" radius="0.02"/>
      </geometry>
      <origin rpy="1.57079632679 0 0" xyz="0 0.075 0"/>
    </collision>
  </link>
  <link name="link_3_FR">
    <visual>
      <geometry>
        <cylinder length="0.3" radius="0.02"/>
      </geometry>
      <origin rpy="1.57079632679 0 0" xyz="0 0.15 0"/>
      <material name="mat_FR">
        <color rgba="1.0 0.5 0.5 1.0"/>
      </material>
    </visual>
    <collision>
      <geometry>
        <cylinder length="0.3" radius="0.02"/>
      </geometry>
      <origin rpy="1.57079632679 0 0" xyz="0 0.15 0"/>
    </collision>
  </link>
  <link name="link_1_HL">
    <visual>
      <geometry>
        <cylinder length="0.1" radius="0.02"/>
      </geometry>
      <origin rpy="1.57079632679 0 0" xyz="0 -0.05 0"/>
      <material name="mat_HL">
        <color rgba="1.0 0.5 0.5 1.0"/>
      </material>
    </visual>
    <collision>
      <geometry>
        <cylinder length="0.1" radius="0.02"/>
      </geometry>
      <origin rpy="1.57079632679 0 0" xyz="0 -0.05 0"/>
    </collision>
  </link>
  <link name="link_2_HL">
    <visual>
      <geometry>
        <cylinder length="0.15" radius="0.02"/>
      </geometry>
      <origin rpy="1.57079632679 0 0" xyz="0 -0.075 0"/>
      <material name="mat_HL">
        <color rgba="1.0 0.5 0.5 1.0"/>
      </material>
    </visual>
    <collision>
      <geometry>
        <cylinder length="0.15" radius="0.02"/>
      </geometry>
      <origin rpy="1.57079632679 0 0" xyz="0 -0.075 0"/>
    </collision>
  </link>
  <link name="link_3_HL">
    <visual>
      <geometry>
        <cylinder length="0.3" radius="0.02"/>
      </geometry>
      <origin rpy="1.57079632679 0 0" xyz="0 -0.15 0"/>
      <material name="mat_HL">
        <color rgba="1.0 0.5 0.5 1.0"/>
      </material>
    </visual>
    <collision>
      <geometry>
        <cylinder length="0.3" radius="0.02"/>
      </geometry>
      <origin rpy="1.57079632679 0 0" xyz="0 -0.15 0"/>
    </collision>
  </link>
  <link name="link_1_HR">
    <visual>
      <geometry>
        <cylinder length="0.1" radius="0.02"/>
      </geometry>
      <origin rpy="1.57079632679 0 0" xyz="0 -0.05 0"/>
      <material name="mat_HR">
        <color rgba="1.0 0.5 0.5 1.0"/>
      </material>
    </visual>
    <collision>
      <geometry>
        <cylinder length="0.1" radius="0.02"/>
      </geometry>
      <origin rpy="1.57079632679 0 0" xyz="0 -0.05 0"/>
    </collision>
  </link>
  <link name="link_2_HR">
    <visual>
      <geometry>
        <cylinder length="0.15" radius="0.02"/>
      </geometry>
      <origin rpy="1.57079632679 0 0" xyz="0 -0.075 0"/>
      <material name="mat_HR">
        <color rgba="1.0 0.5 0.5 1.0"/>
      </material>
    </visual>
    <collision>
      <geometry>
        <cylinder length="0.15" radius="0.02"/>
      </geometry>
      <origin rpy="1.57079632679 0 0" xyz="0 -0.075 0"/>
    </collision>
  </link>
  <link name="link_3_HR">
    <visual>
      <geometry>
        <cylinder length="0.3" radius="0.02"/>
      </geometry>
      <origin rpy="1.57079632679 0 0" xyz="0 -0.15 0"/>
      <material name="mat_HR">
        <color rgba="1.0 0.5 0.5 1.0"/>
      </material>
    </visual>
    <collision>
      <geometry>
        <cylinder length="0.3" radius="0.02"/>
      </geometry>
      <origin rpy="1.57079632679 0 0" xyz="0 -0.15 0"/>
    </collision>
  </link>
  <!--	<joint name="world_jt" type="floating">-->
  <!--		<parent link="world"/>-->
  <!--		<child link="walker_base"/>-->
  <!--	</joint>-->
  <joint name="joint_1_FL" type="continuous">
    <parent link="walker_base"/>
    <child link="link_1_FL"/>
    <origin rpy="0 0 0" xyz="-0.075 0.15 0"/>
    <axis xyz="0 0 -1"/>
  </joint>
  <joint name="joint_2_FL" type="continuous">
    <parent link="link_1_FL"/>
    <child link="link_2_FL"/>
    <origin rpy="0 0 0" xyz="0 0.1 0"/>
    <axis xyz="1 0 0"/>
  </joint>
  <joint name="joint_3_FL" type="continuous">
    <parent link="link_2_FL"/>
    <child link="link_3_FL"/>
    <origin rpy="0 0 0" xyz="0 0.15 0"/>
    <axis xyz="1 0 0"/>
  </joint>
  <joint name="joint_1_FR" type="continuous">
    <parent link="walker_base"/>
    <child link="link_1_FR"/>
    <origin rpy="0 0 0" xyz="0.075 0.15 0"/>
    <axis xyz="0 0 1"/>
  </joint>
  <joint name="joint_2_FR" type="continuous">
    <parent link="link_1_FR"/>
    <child link="link_2_FR"/>
    <origin rpy="0 0 0" xyz="0 0.1 0"/>
    <axis xyz="1 0 0"/>
  </joint>
  <joint name="joint_3_FR" type="continuous">
    <parent link="link_2_FR"/>
    <child link="link_3_FR"/>
    <origin rpy="0 0 0" xyz="0 0.15 0"/>
    <axis xyz="1 0 0"/>
  </joint>
  <joint name="joint_1_HL" type="continuous">
    <parent link="walker_base"/>
    <child link="link_1_HL"/>
    <origin rpy="0 0 0" xyz="-0.075 -0.15 0"/>
    <axis xyz="0 0 1"/>
  </joint>
  <joint name="joint_2_HL" type="continuous">
    <parent link="link_1_HL"/>
    <child link="link_2_HL"/>
    <origin rpy="0 0 0" xyz="0 -0.1 0"/>
    <axis xyz="-1 0 0"/>
  </joint>
  <joint name="joint_3_HL" type="continuous">
    <parent link="link_2_HL"/>
    <child link="link_3_HL"/>
    <origin rpy="0 0 0" xyz="0 -0.15 0"/>
    <axis xyz="-1 0 0"/>
  </joint>
  <joint name="joint_1_HR" type="continuous">
    <parent link="walker_base"/>
    <child link="link_1_HR"/>
    <origin rpy="0 0 0" xyz="0.075 -0.15 0"/>
    <axis xyz="0 0 -1"/>
  </joint>
  <joint name="joint_2_HR" type="continuous">
    <parent link="link_1_HR"/>
    <child link="link_2_HR"/>
    <origin rpy="0 0 0" xyz="0 -0.1 0"/>
    <axis xyz="-1 0 0"/>
  </joint>
  <joint name="joint_3_HR" type="continuous">
    <parent link="link_2_HR"/>
    <child link="link_3_HR"/>
    <origin rpy="0 0 0" xyz="0 -0.15 0"/>
    <axis xyz="-1 0 0"/>
  </joint>
</robot>
